<?xml version="1.0"?>
<robot xmlns:xacro="http://www.ros.org/wiki/xacro" name="stretch_base">
  <xacro:property name="M_PI" value="3.1415926535897931" />
  <xacro:property name="joint_damping" value="0"/>
  <xacro:property name="joint_friction" value="0"/>
  <xacro:property name="joint_spring_stiffness" value="0"/>
  <xacro:property name="joint_spring_reference" value="0"/>

  <material name="blue">
    <color rgba="0 0 0.8 1"/>
  </material>

  <material name="white">
    <color rgba="1 1 1 1"/>
  </material>

  <material name="black">
    <color rgba="0.0 0.0 0.0 1.0"/>
  </material>

  <xacro:macro name="default_inertial" params="mass pos">
    <inertial>
      <origin
        xyz="${pos}"
        rpy="0 0 0" />
      <mass value="${mass}" />
      <inertia
        ixx="0.01"
        ixy="0"
        ixz="0"
        iyy="0.01"
        iyz="0"
        izz="0.01" />
    </inertial>
  </xacro:macro>

  <link
    name="base_link">
    <inertial>
      <origin
        xyz="-0.11587 0.0019426 0.093621"
        rpy="0 0 0" />
      <mass
        value="1.1912" />
      <inertia
        ixx="0.0034667"
        ixy="0"
        ixz="0"
        iyy="0.0052744"
        iyz="0"
        izz="0.0047945" />
    </inertial>
    <visual>
      <origin
        xyz="0 0 0"
        rpy="0 0 0" />
      <geometry>
        <mesh
          filename="package://stretch_gazebo/meshes/base_link.STL" />
      </geometry>
       <material name="white"/>
    </visual>
    <collision>
      <origin
        xyz="0 0 0"
        rpy="0 0 0" />
      <geometry>
        <mesh
          filename="package://stretch_gazebo/meshes/base_link.STL" />
      </geometry>
    </collision>
  </link>

  <link
    name="link_right_wheel">
    <visual>
      <origin
        xyz="0 0 0"
        rpy="0 0 0" />
      <geometry>
        <mesh
          filename="package://stretch_gazebo/meshes/link_right_wheel.STL" />
      </geometry>
      <material name="blue"/>
    </visual>
    <collision>
      <origin
        xyz="0 0 0"
        rpy="0 0 0" />
      <geometry>
        <mesh
          filename="package://stretch_gazebo/meshes/link_right_wheel.STL" />
      </geometry>
    </collision>
    <xacro:default_inertial mass="0.0042721" pos="1.1719E-11 2.0783E-11 0.037544"/>
  </link>

  <joint
    name="joint_right_wheel"
    type="continuous">
    <origin
      xyz="0 -0.17035 0.0508"
      rpy="-1.5708 1.2717E-16 4.8006E-17" />
    <parent
      link="base_link" />
    <child
      link="link_right_wheel" />
    <axis
      xyz="0 0 1" />
    <dynamics damping="${joint_damping}" friction="${joint_friction}" spring_reference="${joint_spring_reference}" spring_stiffness="${joint_spring_stiffness}"/>
  </joint>

  <link
    name="link_left_wheel">
    <visual>
      <origin
        xyz="0 0 0"
        rpy="0 0 0" />
      <geometry>
        <mesh
          filename="package://stretch_gazebo/meshes/link_left_wheel.STL" />
      </geometry>
      <material name="blue"/>
    </visual>
    <collision>
      <origin
        xyz="0 0 0"
        rpy="0 0 0" />
      <geometry>
        <mesh
          filename="package://stretch_gazebo/meshes/link_left_wheel.STL" />
      </geometry>
    </collision>
    <xacro:default_inertial mass="0.0042721" pos="-2.0783E-11 -1.1719E-11 -0.037544"/>
  </link>

  <joint
    name="joint_left_wheel"
    type="continuous">
    <origin
      xyz="0 0.17035 0.0508"
      rpy="-1.5708 2.6317E-16 -8.2057E-19" />
    <parent
      link="base_link" />
    <child
      link="link_left_wheel" />
    <axis
      xyz="0 0 1" />
    <dynamics damping="${joint_damping}" friction="${joint_friction}" spring_reference="${joint_spring_reference}" spring_stiffness="${joint_spring_stiffness}"/>
  </joint>

  <link name="caster_link">
    <collision>
      <geometry>
        <sphere radius="0.032"/>
      </geometry>
      <origin rpy="0 0 0" xyz="0 0 0"/>
      <surface>
        <friction>
          <ode>
            <mu>0</mu>
            <mu2>0</mu2>
            <slip1>1.0</slip1>
            <slip2>1.0</slip2>
          </ode>
        </friction>
      </surface>
    </collision>
    <visual>
      <origin
        xyz="0 0 0"
        rpy="0 0 0" />
      <geometry>
        <mesh
          filename="package://stretch_gazebo/meshes/omni_wheel_m.STL" />
      </geometry>
      <material
        name="">
        <color
          rgba="0.792156862745098 0.819607843137255 0.933333333333333 1" />
      </material>
    </visual>
    <xacro:default_inertial mass="0.01" pos="0 0 0"/>
  </link>

  <joint name="caster_joint" type="fixed">
    <parent link="base_link"/>
    <child link="caster_link"/>
    <origin xyz="-0.245 0.0 0.032" rpy="${-M_PI/2} 0 0"/>
    <axis xyz="0 0 1" />
  </joint>

  <link
    name="link_mast">
    <inertial>
      <origin
        xyz="2.0817E-17 0.7075 -2.7756E-17"
        rpy="0 0 0" />
      <mass
        value="0.18285" />
      <inertia
        ixx="0.0709854511954588"
        ixy="-0.00433428742758457"
        ixz="-0.000186110788697573"
        iyy="0.000437922053342648"
        iyz="-0.00288788257713431"
        izz="0.071104808501661" />
    </inertial>
    <visual>
      <origin
        xyz="0 0 0"
        rpy="0 0 0" />
      <geometry>
        <mesh
          filename="package://stretch_gazebo/meshes/link_mast.STL" />
      </geometry>
      <material name="white"/>
    </visual>
    <collision>
      <origin
        xyz="0 0 0"
        rpy="0 0 0" />
      <geometry>
        <mesh
          filename="package://stretch_gazebo/meshes/link_mast.STL" />
      </geometry>
    </collision>
  </link>

  <joint
    name="joint_mast"
    type="fixed">
    <origin
      xyz="-0.067 0.135 0.0284"
      rpy="1.5708 0 4.8006E-17" />
    <parent
      link="base_link" />
    <child
      link="link_mast" />
    <axis
      xyz="0 0 0" />
  </joint>

  <link
    name="link_head">
    <inertial>
      <origin
        xyz="0.0406850995527703 0.0396956343318414 0.0226500246461012"
        rpy="0 0 0" />
      <mass
        value="0.133027236718691" />
      <inertia
        ixx="0.001"
        ixy="0"
        ixz="0"
        iyy="0.001"
        iyz="0"
        izz="0.001" />
    </inertial>
    <visual>
      <origin
        xyz="0 0 0"
        rpy="0 0 0" />
      <geometry>
        <mesh
          filename="package://stretch_gazebo/meshes/link_head.STL" />
      </geometry>
      <material
        name="">
        <color
          rgba="0.792156862745098 0.819607843137255 0.933333333333333 1" />
      </material>
    </visual>
    <collision>
      <origin
        xyz="0 0 0"
        rpy="0 0 0" />
      <geometry>
        <mesh
          filename="package://stretch_gazebo/meshes/link_head.STL" />
      </geometry>
    </collision>
  </link>

  <joint
    name="joint_head"
    type="fixed">
    <origin
      xyz="0 1.33 0"
      rpy="1.5707963267949 -1.5707963267949 3.1416" />
    <parent
      link="link_mast" />
    <child
      link="link_head" />
    <axis
      xyz="0 0 0" />
  </joint>

  <link
    name="link_head_pan">
    <inertial>
      <origin
        xyz="-0.000326562615178591 0.00850012613776489 0.000130487222982367"
        rpy="0 0 0" />
      <mass
        value="0.0273764496535409" />
      <inertia
        ixx="0.001"
        ixy="0"
        ixz="0"
        iyy="0.001"
        iyz="0"
        izz="0.001" />
    </inertial>
    <visual>
      <origin
        xyz="0 0 0"
        rpy="0 0 0" />
      <geometry>
        <mesh
          filename="package://stretch_gazebo/meshes/link_head_pan.STL" />
      </geometry>
      <material
        name="">
        <color
          rgba="0.792156862745098 0.819607843137255 0.933333333333333 1" />
      </material>
    </visual>
    <collision>
      <origin
        xyz="0 0 0"
        rpy="0 0 0" />
      <geometry>
        <mesh
          filename="package://stretch_gazebo/meshes/link_head_pan.STL" />
      </geometry>
    </collision>
  </link>

  <joint
    name="joint_head_pan"
    type="revolute">
    <origin
      xyz="0.135 0.0731000000000001 -0.00319621125547975"
      rpy="0 0 1.5707963267949" />
    <parent
      link="link_head" />
    <child
      link="link_head_pan" />
    <axis
      xyz="0 0 1" />
    <limit effort="100" lower="-3.9" upper="1.5" velocity="1.0"/>
  </joint>

  <link
    name="link_head_tilt">
    <inertial>
      <origin
        xyz="0.00704566394917504 -0.0212256210929691 0.0302058990060359"
        rpy="0 0 0" />
      <mass
        value="0.090217113313934" />
      <inertia
        ixx="0.001"
        ixy="0"
        ixz="0"
        iyy="0.001"
        iyz="0"
        izz="0.001" />
    </inertial>
    <visual>
      <origin
        xyz="0 0 0"
        rpy="0 0 0" />
      <geometry>
        <mesh
          filename="package://stretch_gazebo/meshes/link_head_tilt.STL" />
      </geometry>
      <material
        name="">
        <color
          rgba="0.792156862745098 0.819607843137255 0.933333333333333 1" />
      </material>
    </visual>
    <collision>
      <origin
        xyz="0 0 0"
        rpy="0 0 0" />
      <geometry>
        <mesh
          filename="package://stretch_gazebo/meshes/link_head_tilt.STL" />
      </geometry>
    </collision>
  </link>

  <joint
    name="joint_head_tilt"
    type="revolute">
    <origin
      xyz="-0.00130000001785262 0.0277624999926072 -0.0533107920897029"
      rpy="1.5707963267949 3.36459255518345E-15 -8.42914893687103E-17" />
    <parent
      link="link_head_pan" />
    <child
      link="link_head_tilt" />
    <axis
      xyz="0 0 1" />
    <limit effort="100" lower="-1.53" upper="0.79" velocity="1.0"/>
  </joint>

  <!-- <link
    name="link_lift">
    <inertial>
      <origin
        xyz="-0.031727 0.038403 0.013361"
        rpy="0 0 0" />
      <mass
        value="0.27218" />
      <inertia
        ixx="0.00052571"
        ixy="0.00014899"
        ixz="-1.9258E-05"
        iyy="0.00030679"
        iyz="-6.2451E-06"
        izz="0.00037324" />
    </inertial>
    <visual>
      <origin
        xyz="0 0 0"
        rpy="0 0 0" />
      <geometry>
        <mesh
          filename="package://stretch_gazebo/meshes/link_lift.STL" />
      </geometry>
      <material name="black"/>
    </visual>
    <collision>
      <origin
        xyz="0 0 0"
        rpy="0 0 0" />
      <geometry>
        <mesh
          filename="package://stretch_gazebo/meshes/link_lift.STL" />
      </geometry>
    </collision>
  </link>

  <joint
    name="joint_lift"
    type="prismatic">
    <origin
      xyz="-0.037385 0.1666 0"
      rpy="-1.5708 1.5708 0" />
    <parent
      link="link_mast" />
    <child
      link="link_lift" />
    <axis
      xyz="0 0 1" />
    <limit effort="100" lower="0.001" upper="1.1" velocity="1.0"/>
    <dynamics damping="0.1" friction="0.1"/>
  </joint> -->
</robot>