<?xml version="1.0"?>
<robot xmlns:xacro="http://www.ros.org/wiki/xacro" name="stretch_base">
  <xacro:property name="M_PI" value="3.1415926535897931" />
  <xacro:property name="joint_damping" value="0"/>
  <xacro:property name="joint_friction" value="0"/>
  <xacro:property name="joint_spring_stiffness" value="0"/>
  <xacro:property name="joint_spring_reference" value="0"/>

  <material name="blue">
    <color rgba="0 0 0.8 1"/>
  </material>

  <material name="white">
    <color rgba="1 1 1 1"/>
  </material>

  <xacro:macro name="default_inertial" params="mass pos">
    <inertial>
      <origin
        xyz="${pos}"
        rpy="0 0 0" />
      <mass value="${mass}" />
      <inertia
        ixx="0.01"
        ixy="0"
        ixz="0"
        iyy="0.01"
        iyz="0"
        izz="0.01" />
    </inertial>
  </xacro:macro>

  <link
    name="base_link">
    <inertial>
      <origin
        xyz="-0.11587 0.0019426 0.093621"
        rpy="0 0 0" />
      <mass
        value="1.1912" />
      <inertia
        ixx="0.0034667"
        ixy="0"
        ixz="0"
        iyy="0.0052744"
        iyz="0"
        izz="0.0047945" />
    </inertial>
    <visual>
      <origin
        xyz="0 0 0"
        rpy="0 0 0" />
      <geometry>
        <mesh
          filename="package://stretch_gazebo/meshes/base_link.STL" />
      </geometry>
       <material name="white"/>
    </visual>
    <collision>
      <origin
        xyz="0 0 0"
        rpy="0 0 0" />
      <geometry>
        <mesh
          filename="package://stretch_gazebo/meshes/base_link.STL" />
      </geometry>
    </collision>
  </link>

  <link
    name="link_right_wheel">
    <visual>
      <origin
        xyz="0 0 0"
        rpy="0 0 0" />
      <geometry>
        <mesh
          filename="package://stretch_gazebo/meshes/link_right_wheel.STL" />
      </geometry>
      <material name="blue"/>
    </visual>
    <collision>
      <origin
        xyz="0 0 0"
        rpy="0 0 0" />
      <geometry>
        <mesh
          filename="package://stretch_gazebo/meshes/link_right_wheel.STL" />
      </geometry>
    </collision>
    <xacro:default_inertial mass="0.0042721" pos="1.1719E-11 2.0783E-11 0.037544"/>
  </link>

  <joint
    name="joint_right_wheel"
    type="continuous">
    <origin
      xyz="0 -0.17035 0.0508"
      rpy="-1.5708 1.2717E-16 4.8006E-17" />
    <parent
      link="base_link" />
    <child
      link="link_right_wheel" />
    <axis
      xyz="0 0 1" />
    <dynamics damping="${joint_damping}" friction="${joint_friction}" spring_reference="${joint_spring_reference}" spring_stiffness="${joint_spring_stiffness}"/>
  </joint>

  <link
    name="link_left_wheel">
    <visual>
      <origin
        xyz="0 0 0"
        rpy="0 0 0" />
      <geometry>
        <mesh
          filename="package://stretch_gazebo/meshes/link_left_wheel.STL" />
      </geometry>
      <material name="blue"/>
    </visual>
    <collision>
      <origin
        xyz="0 0 0"
        rpy="0 0 0" />
      <geometry>
        <mesh
          filename="package://stretch_gazebo/meshes/link_left_wheel.STL" />
      </geometry>
    </collision>
    <xacro:default_inertial mass="0.0042721" pos="-2.0783E-11 -1.1719E-11 -0.037544"/>
  </link>

  <joint
    name="joint_left_wheel"
    type="continuous">
    <origin
      xyz="0 0.17035 0.0508"
      rpy="-1.5708 2.6317E-16 -8.2057E-19" />
    <parent
      link="base_link" />
    <child
      link="link_left_wheel" />
    <axis
      xyz="0 0 1" />
    <dynamics damping="${joint_damping}" friction="${joint_friction}" spring_reference="${joint_spring_reference}" spring_stiffness="${joint_spring_stiffness}"/>
  </joint>

  <link name="caster_link">
    <collision>
      <geometry>
        <sphere radius="0.032"/>
      </geometry>
      <origin rpy="0 0 0" xyz="0 0 0"/>
      <surface>
        <friction>
          <ode>
            <mu>0</mu>
            <mu2>0</mu2>
            <slip1>1.0</slip1>
            <slip2>1.0</slip2>
          </ode>
        </friction>
      </surface>
    </collision>
    <visual>
      <origin
        xyz="0 0 0"
        rpy="0 0 0" />
      <geometry>
        <mesh
          filename="package://stretch_gazebo/meshes/omni_wheel_m.STL" />
      </geometry>
      <material
        name="">
        <color
          rgba="0.792156862745098 0.819607843137255 0.933333333333333 1" />
      </material>
    </visual>
    <xacro:default_inertial mass="0.01" pos="0 0 0"/>
  </link>

  <joint name="caster_joint" type="fixed">
    <parent link="base_link"/>
    <child link="caster_link"/>
    <origin xyz="-0.245 0.0 0.032" rpy="${-M_PI/2} 0 0"/>
    <axis xyz="0 0 1" />
  </joint>
</robot>